Workbook

Sheet Backend tests
A1: Backend tests: These are test cases for Sprint 1 stories. Stories not part of the Sprint 1 backlog should not be displayed here.
A3: US_01 As the development team, we need clean per-eye labels, a patient-level split and preprocessed photos, so the model can be trained and tested fairly.
A4: TC | B4: TC Title | C4: Step Description | D4: Expected Results | E4: Execution Status | F4: Execution date | G4: Tester
A5: TC_01_01 | B5: Verification script passes the real label file | C5: 1. Clean clone of main. 2. Run: python scripts/verify_labels.py labels/eye_labels_task7.csv --images "data/Internal/ODIR-5K/Training Images" --manifest data | D5: All checks pass | E5: pass | F5: Oct 4 | G5: Anel
A6: TC_01_02 | B6: Verification script reports a wrong file as wrong | C6: 1. Run: python scripts/verify_labels.py labels/labels_stub.csv | D6: Stub file fails the count and split checks | E6: pass | F6: Oct 4 | G6: Anel
A7: TC_01_03 | B7: Label file has all columns and 7,000 eyes | C7: 1. Run: python scripts/verify_labels.py labels/eye_labels_task7.csv --images "data/Internal/ODIR-5K/Training Images" --manifest data 2. Read the columns and rows lines. | D7: 11 columns present; 7,000 rows | E7: pass | F7: Oct 4 | G7: Anel
A8: TC_01_04 | B8: Per-eye disease counts are correct | C8: 1. Same run. 2. Read the count lines. | D8: Cataract 313, glaucoma 282, suspected glaucoma 44, media opacity 63, quality flag 426, excluded 30, normal 2,818, diabetic retinopathy 1,796 | E8: pass | F8: Oct 4 | G8: Anel
A9: TC_01_05 | B9: One-eye and both-condition patient counts | C9: 1. Same run. 2. Read the patient count lines. | D9: Cataract in one eye only 111; glaucoma in one eye only 72; both conditions 1 | E9: pass | F9: Oct 4 | G9: Anel
A10: TC_01_06 | B10: Every filename exists and data matches the manifest | C10: 1. Same run. 2. Read the filename and MANIFEST lines. | D10: No duplicate filenames; every image found; all 10,324 data files match MANIFEST.sha256 | E10: pass | F10: Oct 4 | G10: Anel
A11: TC_01_07 | B11: No patient in two splits | C11: 1. Same run. 2. Read the split lines. | D11: No patient in more than one of train, validation, test | E11: pass | F11: Oct 4 | G11: Anel
A12: TC_01_08 | B12: Unusable and held-out eyes kept out of training and testing | C12: 1. Same run. | D12: No suspected glaucoma, media opacity or excluded eye in train, validation or test | E12: pass | F12: Oct 4 | G12: Anel
A13: TC_01_09 | B13: Both-condition patient placed in training | C13: 1. Same run. | D13: Patient with cataract and glaucoma is in train | E13: pass | F13: Oct 4 | G13: Anel
A14: TC_01_10 | B14: Split shares are 70 / 15 / 15 by patient | C14: 1. Same run. | D14: About 70%, 15%, 15% of patients | E14: pass | F14: Oct 4 | G14: Anel
A15: TC_01_11 | B15: Every photo has a preprocessed copy | C15: 1. Run: python scripts/preprocess_images.py 2. Count files per dataset in Preprocessed/. | D15: ODIR 7,000; ORIGA 650; DRISHTI-GS 101; ACRIMA 705; retina_dataset_2016 601 | E15: pass | F15: Oct 4 | G15: Anel
... A19: TC_01_15 | B19: Data pipeline scripts run from a clean clone | C19: 1. Fresh clone of main (88d55db). 2. Run every test above. | D19: Scripts run without import errors | E19: pass | F19: Oct 4 | G19: Anel
A21: US_02 As a screening technician, I want one photo to give both a cataract and a glaucoma result, so I can triage both conditions in one step.
A22: TC | B22: TC Title | C22: Step Description | D22: Expected Results | E22: Execution Status | F22: Execution date | G22: Tester
A23: TC_02_01 | B23: Training smoke test runs end to end | C23: 1. Preprocess ODIR (SCRUM-28). 2. Run: python scripts/test_train_dual.py | D23: Training batches and validation batches run with finite loss, no errors | E23: pass | F23: Oct 4 | G23: Anel
A25: US_03 As a reviewer, I want the model tested on outside datasets it never trained on, so I can trust that it works beyond ODIR-5K.
A26: TC | B26: TC Title | C26: Step Description | D26: Expected Results | E26: Execution Status | F26: Execution date | G26: Tester
A27: TC_03_01 | B27: ORIGA labels | C27: 1. Run: python scripts/build_external_labels.py | D27: 650 photos, 168 glaucoma | E27: pass | F27: Oct 4 | G27: Anel
A28: TC_03_02 | B28: DRISHTI-GS labels and spreadsheet cross-check | C28: 1. Same run. | D28: 101 photos, 70 glaucoma; folder labels agree with the notching spreadsheet | E28: pass | F28: Oct 4 | G28: Anel
A29: TC_03_03 | B29: ACRIMA labels | C29: 1. Same run. | D29: 705 photos, 396 glaucoma | E29: pass | F29: Oct 4 | G29: Anel
A30: TC_03_04 | B30: retina_dataset_2016 labels | C30: 1. Same run. | D30: 601 photos, 100 cataract, 101 glaucoma | E30: pass | F30: Oct 4 | G30: Anel
A31: TC_03_05 | B31: Rebuilt label files match the committed ones | C31: 1. After the run: git status labels/ | D31: No changes to labels/external | E31: pass | F31: Oct 4 | G31: Anel
A32: TC_03_06 | B32: No identical copy of an ODIR photo in retina_dataset_2016 | C32: 1. Run: python scripts/check_dataset_overlap.py | D32: Matching fingerprints: 0. The check finds identical files only; resized or edited copies are not detected. | E32: pass | F32: Oct 4 | G32: Anel
A33: TC_03_07 | B33: A planted identical copy is caught | C33: 1. Copy one ODIR photo, renamed, into a test folder next to a retina photo. 2. Point the script at that folder. | D33: Matching fingerprints: 1 | E33: pass | F33: Oct 4 | G33: Anel
A34: TC_03_08 | B34: Calibration tests pass | C34: 1. Copy of main (12db1f8). 2. Run: python -m pytest tests/test_calibration_selection.py tests/test_calibration_provenance.py | D34: 18 passed | E34: pass | F34: Oct 18 | G34: Anel
A35: TC_03_09 | B35: Calibration uses the validation split only | C35: 1. Copy of main (12db1f8). 2. Read every results/calibration/*_validation.csv and results/calibration/shared/*_validation.csv with its .meta.json. 3. Match the filenames against the validation rows of labels/eye_labels_task7.csv. | D35: 9 score files (6 single-disease, 3 shared in shared/), 1,024 rows each; filenames match the 1,024 validation eyes exactly; all marked split = validation; no train, test or external eye | E35: pass | F35: Oct 18 | G35: Anel
A36: TC_03_10 | B36: External label files are test-only | C36: 1. Copy of develop (0f21e1f, PR #43). 2. Read labels/external/*.csv. | D36: 2,057 rows across ORIGA, DRISHTI-GS, ACRIMA and retina_dataset_2016; every row has split = test | E36: pass | F36: Oct 16 | G36: Anel
A37: TC_03_11 | B37: External evaluation protocol is written | C37: 1. Copy of develop (0f21e1f, PR #43). 2. Open documents/evaluation/external_validation_protocol.md (SCRUM-44). | D37: Protocol lists the metrics, the freeze rule and the 2,057 test entries; counts match the label files | E37: pass | F37: Oct 16 | G37: Anel
... A41: TC_03_15 | B41: Low-quality photo check uses the frozen settings | C41: 1. Open results/calibration/final_holdout_report.md and .json. 2. Check its settings SHA-256 against frozen_settings.json. 3. Read the shared seed 42 row. | D41: Runs once on the 21 low-quality eyes (19 patients) with the frozen settings (SHA matches). Shared seed 42: 8 of 21 Uncertain, refer; 15 of 21 referred in total, including those 8. Counts only, no accuracy claim. | E41: pass | F41: Oct 17 | G41: Negar (checked by Anel)
A43: US_04 As a screening technician, I want to upload a patient's fundus photo and see a clear cataract and glaucoma result, so I can decide quickly whether the patient should see an eye specialist.
A44: TC | B44: TC Title | C44: Step Description | D44: Expected Results | E44: Execution Status | F44: Execution date | G44: Tester
A45: TC_04_01 | B45: Login is required | C45: 1. On branch task-api-mock (PR #35). 2. Run: python -m pytest tests/test_api.py -v | D45: Without logging in, the patient list returns 401; a wrong password returns 401 | E45: pass | F45: Oct 10 | G45: Anel
A46: TC_04_02 | B46: Logout ends the session | C46: 1. On branch task-api-mock (PR #35). 2. Run: python -m pytest tests/test_api.py -v | D46: After logout, the current-user call returns 401 | E46: pass | F46: Oct 10 | G46: Anel
A47: TC_04_03 | B47: Demo data loads | C47: 1. On branch task-api-mock (PR #35). 2. Run: python -m pytest tests/test_api.py -v | D47: 4 made-up patients sorted by last name; 5 screenings listed newest first | E47: pass | F47: Oct 10 | G47: Anel
A48: TC_04_04 | B48: New patient gets the next ID | C48: 1. On branch task-api-mock (PR #35). 2. Run: python -m pytest tests/test_api.py -v | D48: Next ID is P-005; a patient with an empty name is rejected (422) | E48: pass | F48: Oct 10 | G48: Anel
A49: TC_04_05 | B49: A fundus photo is screened | C49: 1. On branch task-api-mock (PR #35). 2. Run: python -m pytest tests/test_api.py -v | D49: Photo passes the quality check; screening returns a cataract and a glaucoma result, an overall result and both heatmaps; model is marked as mock | E49: pass | F49: Oct 10 | G49: Anel
A50: TC_04_06 | B50: A failed photo is never screened | C50: 1. On branch task-api-mock (PR #35). 2. Run: python -m pytest tests/test_api.py -v | D50: A screenshot fails as not_fundus and cannot be screened (409); a non-image file fails as unreadable | E50: pass | F50: Oct 10 | G50: Anel
...

Sheet Frontend tests
A1: DUAL Sprint 1 test cases: frontend
A3: US_04 As a screening technician, I want to upload a patient's fundus photo and see a clear cataract and glaucoma result, so I can decide quickly whether the patient should see an eye specialist.
A4: TC | B4: TC Title | C4: Step Description | D4: Expected Results | E4: Execution Status | F4: Tester
A5: TC_04_15 | B5: Select patient and eye | C5: Open Upload. Choose a demo patient and select Left or Right. | D5: Selected patient and eye appear before screening. | E5: pass | F5: Bhoami
A6: TC_04_16 | B6: Open main pages | C6: Use navigation to open Home, Upload, Results, History and About. | D6: Available pages open with the correct content. | E6: pass | F6: Bhoami
A7: TC_04_17 | B7: Upload and preview a photo | C7: Choose a JPG/PNG fundus photo. Review its preview before screening. | D7: Selected photo appears in the upload preview. | E7: pass | F7: Bhoami
A8: TC_04_18 | B8: Reject unsupported files | C8: Try uploading a non-image file, such as PDF or TXT. | D8: Unsupported file is rejected with clear feedback. | E8: pass | F8: Bhoami
A9: TC_04_19 | B9: Reject poor-quality image | C9: Upload a poor-quality fundus photograph and submit for screening. | D9: Quality warning appears; normal screening does not proceed. | E9: pass | F9: Bhoami
A10: TC_04_20 | B10: Show screening results | C10: Submit an accepted fundus photo and open the Results page. | D10: Overall result and separate cataract/glaucoma results appear. | E10: pass | F10: Bhoami
A11: TC_04_21 | B11: Display risk information | C11: Review the condition scores, thresholds, and result details. | D11: Risk information is shown for available mock-model outputs. | E11: pass | F11: Bhoami
A12: TC_04_22 | B12: Handle Refer / Uncertain | C12: Review screens for Refer and Uncertain outputs when returned. | D12: Correct label and follow-up guidance are displayed. | E12: pass | F12: Bhoami
A13: TC_04_23 | B13: Review screening history | C13: Open History after completing a screening. | D13: Stored screening records can be retrieved and reviewed. | E13: pass | F13: Bhoami
A14: TC_04_24 | B14: Switch light/dark theme | C14: Use the theme toggle on the application interface. | D14: Theme changes and content remains readable. | E14: pass | F14: Bhoami
A15: TC_04_25 | B15: Check mobile layout | C15: Open Home, Upload, Results and History at phone width. | D15: Content fits without cutoff or unwanted horizontal scrolling. | E15: pass | F15: Bhoami
A16: TC_04_26 | B16: Use demo patient records | C16: Review the patient selection and displayed patient details. | D16: Prototype uses fictional patient records, not real patient data. | E16: pass | F16: Bhoami

Sheet Test summary
A1: DUAL Sprint 1 test summary
A3: Story ID | B3: Feature | C3: Area | D3: Total | E3: Passed | F3: Failed | G3: Not run
A4: US_01 | B4: Data Pipeline | C4: Backend | D4: =SUM(E4:G4) -> 15 | E4: =COUNTIFS('Backend tests'!$A$1:$A$300,"TC_01_*",'Backend tests'!$E$1:$E$300,"pass") -> 15 | F4: =COUNTIFS('Backend tests'!$A$1:$A$300,"TC_01_*",'Backend tests'!$E$1:$E$300,"fail") -> 0 | G4: =COUNTIFS('Backend tests'!$A$1:$A$300,"TC_01_*",'Backend tests'!$E$1:$E$300,"not run") -> 0
A5: US_02 | B5: Dual-Head Model | C5: Backend | D5: =SUM(E5:G5) -> 1 | E5: =COUNTIFS('Backend tests'!$A$1:$A$300,"TC_02_*",'Backend tests'!$E$1:$E$300,"pass") -> 1 | F5: =COUNTIFS('Backend tests'!$A$1:$A$300,"TC_02_*",'Backend tests'!$E$1:$E$300,"fail") -> 0 | G5: =COUNTIFS('Backend tests'!$A$1:$A$300,"TC_02_*",'Backend tests'!$E$1:$E$300,"not run") -> 0
A6: US_03 | B6: External Test Sets | C6: Backend | D6: =SUM(E6:G6) -> 15 | E6: =COUNTIFS('Backend tests'!$A$1:$A$300,"TC_03_*",'Backend tests'!$E$1:$E$300,"pass") -> 15 | F6: =COUNTIFS('Backend tests'!$A$1:$A$300,"TC_03_*",'Backend tests'!$E$1:$E$300,"fail") -> 0 | G6: =COUNTIFS('Backend tests'!$A$1:$A$300,"TC_03_*",'Backend tests'!$E$1:$E$300,"not run") -> 0
A7: US_04 | B7: App Prototype (API) | C7: Backend | D7: =SUM(E7:G7) -> 14 | E7: =COUNTIFS('Backend tests'!$A$1:$A$300,"TC_04_*",'Backend tests'!$E$1:$E$300,"pass") -> 14 | F7: =COUNTIFS('Backend tests'!$A$1:$A$300,"TC_04_*",'Backend tests'!$E$1:$E$300,"fail") -> 0 | G7: =COUNTIFS('Backend tests'!$A$1:$A$300,"TC_04_*",'Backend tests'!$E$1:$E$300,"not run") -> 0
A8: US_04 | B8: App Prototype (screens) | C8: Frontend | D8: =SUM(E8:G8) -> 12 | E8: =COUNTIFS('Frontend tests'!$A$1:$A$300,"TC_04_*",'Frontend tests'!$E$1:$E$300,"pass") -> 12 | F8: =COUNTIFS('Frontend tests'!$A$1:$A$300,"TC_04_*",'Frontend tests'!$E$1:$E$300,"fail") -> 0 | G8: =COUNTIFS('Frontend tests'!$A$1:$A$300,"TC_04_*",'Frontend tests'!$E$1:$E$300,"not run") -> 0
A9: US_05 | B9: Photo Quality Check | C9: Backend | D9: =SUM(E9:G9) -> 17 | E9: =COUNTIFS('Backend tests'!$A$1:$A$300,"TC_05_*",'Backend tests'!$E$1:$E$300,"pass") -> 17 | F9: =COUNTIFS('Backend tests'!$A$1:$A$300,"TC_05_*",'Backend tests'!$E$1:$E$300,"fail") -> 0 | G9: =COUNTIFS('Backend tests'!$A$1:$A$300,"TC_05_*",'Backend tests'!$E$1:$E$300,"not run") -> 0
A10: US_06 | B10: Model Ablation | C10: Backend | D10: =SUM(E10:G10) -> 8 | E10: =COUNTIFS('Backend tests'!$A$1:$A$300,"TC_06_*",'Backend tests'!$E$1:$E$300,"pass") -> 8 | F10: =COUNTIFS('Backend tests'!$A$1:$A$300,"TC_06_*",'Backend tests'!$E$1:$E$300,"fail") -> 0 | G10: =COUNTIFS('Backend tests'!$A$1:$A$300,"TC_06_*",'Backend tests'!$E$1:$E$300,"not run") -> 0
A11: Total | D11: =SUM(D4:D10) -> 82 | E11: =SUM(E4:E10) -> 82 | F11: =SUM(F4:F10) -> 0 | G11: =SUM(G4:G10) -> 0
A13: Sprint 1 test cases. Totals update automatically from the Backend tests and Frontend tests tabs.
